first one
Could not find platform independent libraries <prefix>                                                                                                   
Traceback (most recent call last):
  File "C:\Users\semen\Desktop\botik\myenv\Lib\site-packages\urllib3\connectionpool.py", line 466, in _make_request
    self._validate_conn(conn)
  File "C:\Users\semen\Desktop\botik\myenv\Lib\site-packages\urllib3\connectionpool.py", line 1095, in _validate_conn
    conn.connect()
  File "C:\Users\semen\Desktop\botik\myenv\Lib\site-packages\urllib3\connection.py", line 652, in connect
    sock_and_verified = _ssl_wrap_socket_and_match_hostname(
                        ^^^^^^^^^^^^^^^^^^^^^^^^^^^^^^^^^^^^
  File "C:\Users\semen\Desktop\botik\myenv\Lib\site-packages\urllib3\connection.py", line 805, in _ssl_wrap_socket_and_match_hostname
    ssl_sock = ssl_wrap_socket(
               ^^^^^^^^^^^^^^^^
  File "C:\Users\semen\Desktop\botik\myenv\Lib\site-packages\urllib3\util\ssl_.py", line 465, in ssl_wrap_socket
    ssl_sock = _ssl_wrap_socket_impl(sock, context, tls_in_tls, server_hostname)
               ^^^^^^^^^^^^^^^^^^^^^^^^^^^^^^^^^^^^^^^^^^^^^^^^^^^^^^^^^^^^^^^^^
  File "C:\Users\semen\Desktop\botik\myenv\Lib\site-packages\urllib3\util\ssl_.py", line 509, in _ssl_wrap_socket_impl
    return ssl_context.wrap_socket(sock, server_hostname=server_hostname)
           ^^^^^^^^^^^^^^^^^^^^^^^^^^^^^^^^^^^^^^^^^^^^^^^^^^^^^^^^^^^^^^
  File "C:\Users\semen\AppData\Local\Programs\Python\Python312\Lib\ssl.py", line 455, in wrap_socket
    return self.sslsocket_class._create(
           ^^^^^^^^^^^^^^^^^^^^^^^^^^^^^
  File "C:\Users\semen\AppData\Local\Programs\Python\Python312\Lib\ssl.py", line 1042, in _create
    self.do_handshake()
  File "C:\Users\semen\AppData\Local\Programs\Python\Python312\Lib\ssl.py", line 1320, in do_handshake
    self._sslobj.do_handshake()
TimeoutError: _ssl.c:983: The handshake operation timed out

The above exception was the direct cause of the following exception:

Traceback (most recent call last):
  File "C:\Users\semen\Desktop\botik\myenv\Lib\site-packages\requests\adapters.py", line 667, in send
    resp = conn.urlopen(
           ^^^^^^^^^^^^^
  File "C:\Users\semen\Desktop\botik\myenv\Lib\site-packages\urllib3\connectionpool.py", line 843, in urlopen
    retries = retries.increment(
              ^^^^^^^^^^^^^^^^^^
  File "C:\Users\semen\Desktop\botik\myenv\Lib\site-packages\urllib3\util\retry.py", line 474, in increment
    raise reraise(type(error), error, _stacktrace)
          ^^^^^^^^^^^^^^^^^^^^^^^^^^^^^^^^^^^^^^^^
  File "C:\Users\semen\Desktop\botik\myenv\Lib\site-packages\urllib3\util\util.py", line 39, in reraise
    raise value
  File "C:\Users\semen\Desktop\botik\myenv\Lib\site-packages\urllib3\connectionpool.py", line 789, in urlopen
    response = self._make_request(
               ^^^^^^^^^^^^^^^^^^^
  File "C:\Users\semen\Desktop\botik\myenv\Lib\site-packages\urllib3\connectionpool.py", line 490, in _make_request
    raise new_e
  File "C:\Users\semen\Desktop\botik\myenv\Lib\site-packages\urllib3\connectionpool.py", line 468, in _make_request
    self._raise_timeout(err=e, url=url, timeout_value=conn.timeout)
  File "C:\Users\semen\Desktop\botik\myenv\Lib\site-packages\urllib3\connectionpool.py", line 369, in _raise_timeout
    raise ReadTimeoutError(
urllib3.exceptions.ReadTimeoutError: HTTPSConnectionPool(host='api.telegram.org', port=443): Read timed out. (read timeout=15)

During handling of the above exception, another exception occurred:

Traceback (most recent call last):
  File "C:\Users\semen\Desktop\botik\main.py", line 538, in <module>
    bot.polling(none_stop=True, timeout=30)
  File "C:\Users\semen\Desktop\botik\myenv\Lib\site-packages\telebot\__init__.py", line 1178, in polling
    self.__threaded_polling(non_stop=non_stop, interval=interval, timeout=timeout, long_polling_timeout=long_polling_timeout,
  File "C:\Users\semen\Desktop\botik\myenv\Lib\site-packages\telebot\__init__.py", line 1253, in __threaded_polling
    raise e
  File "C:\Users\semen\Desktop\botik\myenv\Lib\site-packages\telebot\__init__.py", line 1215, in __threaded_polling
    self.worker_pool.raise_exceptions()
  File "C:\Users\semen\Desktop\botik\myenv\Lib\site-packages\telebot\util.py", line 150, in raise_exceptions
    raise self.exception_info
  File "C:\Users\semen\Desktop\botik\myenv\Lib\site-packages\telebot\util.py", line 93, in run
    task(*args, **kwargs)
  File "C:\Users\semen\Desktop\botik\myenv\Lib\site-packages\telebot\__init__.py", line 8707, in _run_middlewares_and_handler
    result = handler['function'](message)
             ^^^^^^^^^^^^^^^^^^^^^^^^^^^^
  File "C:\Users\semen\Desktop\botik\main.py", line 232, in show_overall_stats
    bot.send_message(message.chat.id, response)
  File "C:\Users\semen\Desktop\botik\myenv\Lib\site-packages\telebot\__init__.py", line 1755, in send_message
    apihelper.send_message(
  File "C:\Users\semen\Desktop\botik\myenv\Lib\site-packages\telebot\apihelper.py", line 273, in send_message
    return _make_request(token, method_url, params=payload, method='post')
           ^^^^^^^^^^^^^^^^^^^^^^^^^^^^^^^^^^^^^^^^^^^^^^^^^^^^^^^^^^^^^^^
  File "C:\Users\semen\Desktop\botik\myenv\Lib\site-packages\telebot\apihelper.py", line 162, in _make_request
    result = _get_req_session().request(
             ^^^^^^^^^^^^^^^^^^^^^^^^^^^
  File "C:\Users\semen\Desktop\botik\myenv\Lib\site-packages\requests\sessions.py", line 589, in request
    resp = self.send(prep, **send_kwargs)
           ^^^^^^^^^^^^^^^^^^^^^^^^^^^^^^
  File "C:\Users\semen\Desktop\botik\myenv\Lib\site-packages\requests\sessions.py", line 703, in send
    r = adapter.send(request, **kwargs)
        ^^^^^^^^^^^^^^^^^^^^^^^^^^^^^^^
  File "C:\Users\semen\Desktop\botik\myenv\Lib\site-packages\requests\adapters.py", line 713, in send
    raise ReadTimeout(e, request=request)
requests.exceptions.ReadTimeout: HTTPSConnectionPool(host='api.telegram.org', port=443): Read timed out. (read timeout=15)


second
